<mujoco model="fr3_dual">
  <compiler angle="radian" meshdir="assets"/>

  <option integrator="implicitfast"/>

  <default>
    <default class="fr3">
      <joint armature="0.1" damping="1"/>
      <!--<position inheritrange="1"/>-->
      <default class="visual">
        <geom type="mesh" group="2" contype="0" conaffinity="0"/>
      </default>
      <default class="collision">
        <geom type="mesh" group="3" contype="1" conaffinity="1"/>
      </default>
      <default class="finger">
        <joint axis="0 1 0" type="slide" range="0 0.04"/>
      </default>
      <site size="0.001" rgba="0.5 0.5 0.5 0.3" group="4"/>
    </default>
  </default>

  <asset>
    <material name="black" rgba=".2 .2 .2 1"/>
    <material name="white" rgba="1 1 1 1"/>
    <material name="red" rgba="1 0.072272 0.039546 1"/>
    <material name="gray" rgba="0.863156 0.863156 0.863157 1"/>
    <material name="button_green" rgba="0.102241 0.571125 0.102242 1"/>
    <material name="button_red" rgba="0.520996 0.008023 0.013702 1"/>
    <material name="button_blue" rgba="0.024157 0.445201 0.737911 1"/>

    <mesh file="link0_0.obj"/>
    <mesh file="link0_1.obj"/>
    <mesh file="link0_2.obj"/>
    <mesh file="link0_3.obj"/>
    <mesh file="link0_4.obj"/>
    <mesh file="link0_5.obj"/>
    <mesh file="link0_6.obj"/>
    <mesh file="link1.obj"/>
    <mesh file="link2.obj"/>
    <mesh file="link3_0.obj"/>
    <mesh file="link3_1.obj"/>
    <mesh file="link4_0.obj"/>
    <mesh file="link4_1.obj"/>
    <mesh file="link5_0.obj"/>
    <mesh file="link5_1.obj"/>
    <mesh file="link5_2.obj"/>
    <mesh file="link6_0.obj"/>
    <mesh file="link6_1.obj"/>
    <mesh file="link6_2.obj"/>
    <mesh file="link6_3.obj"/>
    <mesh file="link6_4.obj"/>
    <mesh file="link6_5.obj"/>
    <mesh file="link6_6.obj"/>
    <mesh file="link6_7.obj"/>
    <mesh file="link7_0.obj"/>
    <mesh file="link7_1.obj"/>
    <mesh file="link7_2.obj"/>
    <mesh file="link7_3.obj"/>

    <mesh name="link0_coll" file="link0.stl"/>
    <mesh name="link1_coll" file="link1.stl"/>
    <mesh name="link2_coll" file="link2.stl"/>
    <mesh name="link3_coll" file="link3.stl"/>
    <mesh name="link4_coll" file="link4.stl"/>
    <mesh name="link5_coll" file="link5.stl"/>
    <mesh name="link6_coll" file="link6.stl"/>
    <mesh name="link7_coll" file="link7.stl"/>
    
    <!-- Panda gripper meshes -->
    <mesh file="hand_0.obj"/>
    <mesh file="hand_1.obj"/>
    <mesh file="hand_2.obj"/>
    <mesh file="hand_3.obj"/>
    <mesh file="hand_4.obj"/>
    <mesh name="hand_coll" file="hand.stl"/>
    <mesh file="finger_0.obj"/>
    <mesh file="finger_1.obj"/>
    
    <mesh name="duo_base.stl" file="body/Duo_Franka_Base.stl"/>
  </asset>

  <worldbody>
    <!-- SHARED BASE PLATFORM -->
    <body name="base_link" pos="0 0 0" quat="1.0 0.0 0.0 0.0">
      <!-- <geom type="mesh" mesh="duo_base" rgba="0.5 0.5 0.5 1" group="2" contype="0" conaffinity="0"/> -->

      <geom name="body_link0_collision" pos="0.0 0.0 0.0" quat="1.0 0.0 0.0 0.0" type="mesh" mesh="duo_base.stl" class="collision" />
      <geom name="body_link0_visual_0" pos="0.0 0.0 0.0" quat="1.0 0.0 0.0 0.0" type="mesh" mesh="duo_base.stl" class="visual" />
      
      <!-- LEFT ARM -->
      <body name="left_base" pos="0.056 0.119324 0.194376" quat="0.9239 -0.3827 0 0" childclass="fr3">
        <body name="left_fr3_link0">
          <geom mesh="link0_0" material="black" class="visual"/>
          <geom mesh="link0_1" material="white" class="visual"/>
          <geom mesh="link0_2" material="white" class="visual"/>
          <geom mesh="link0_3" material="white" class="visual"/>
          <geom mesh="link0_4" material="white" class="visual"/>
          <geom mesh="link0_5" material="red" class="visual"/>
          <geom mesh="link0_6" material="black" class="visual"/>
          <geom name="left_fr3_link0_collision" mesh="link0_coll" class="collision"/>
          <body name="left_fr3_link1" pos="0 0 0.333">
            <inertial pos="4.128e-07 -0.0181251 -0.0386036" quat="0.999901 0.0021545 0.00429041 0.0132325" mass="2.92747"
              diaginertia="0.0186043 0.0181194 0.00538716"/>
            <joint name="left_fr3_joint1" axis="0 0 1" range="-2.7437 2.7437" actuatorfrcrange="-87 87" frictionloss="0.5" damping="10.0"/>
            <geom name="left_fr3_link1_collision" class="collision" mesh="link1_coll"/>
            <geom material="white" mesh="link1" class="visual"/>
            <body name="left_fr3_link2" quat="1 -1 0 0">
              <inertial pos="0.00318289 -0.0743222 0.00881461" quat="0.356855 0.680818 -0.434812 0.469126" mass="2.93554"
                diaginertia="0.0299291 0.0299291 0.0299291"/>
              <joint name="left_fr3_joint2" axis="0 0 1" range="-1.7837 1.7837" actuatorfrcrange="-87 87" frictionloss="0.5" damping="10.0"/>
              <geom material="white" mesh="link2" class="visual"/>
              <geom name="left_fr3_link2_collision" class="collision" mesh="link2_coll"/>
              <body name="left_fr3_link3" pos="0 -0.316 0" quat="1 1 0 0">
                <inertial pos="0.0407016 -0.00482006 -0.0289731" quat="0.950032 -0.148357 0.229935 0.150201" mass="2.2449"
                  diaginertia="0.0140109 0.0140109 0.0140109"/>
                <joint name="left_fr3_joint3" axis="0 0 1" range="-2.9007 2.9007" actuatorfrcrange="-87 87" frictionloss="0.5" damping="10.0"/>
                <geom mesh="link3_0" material="white" class="visual"/>
                <geom mesh="link3_1" material="black" class="visual"/>
                <geom name="left_fr3_link3_collision" class="collision" mesh="link3_coll"/>
                <body name="left_fr3_link4" pos="0.0825 0 0" quat="1 1 0 0">
                  <inertial pos="-0.0459101 0.0630493 -0.00851879" quat="0.23761 0.892458 -0.00078702 0.383484"
                    mass="2.6156" diaginertia="0.0206104 0.0206104 0.0206104"/>
                  <joint name="left_fr3_joint4" axis="0 0 1" range="-3.0421 -0.1518" actuatorfrcrange="-87 87" frictionloss="0.5" damping="10.0"/>
                  <geom mesh="link4_0" material="white" class="visual"/>
                  <geom mesh="link4_1" material="black" class="visual"/>
                  <geom name="left_fr3_link4_collision" class="collision" mesh="link4_coll"/>
                  <body name="left_fr3_link5" pos="-0.0825 0.384 0" quat="1 -1 0 0">
                    <inertial pos="-0.00160396 0.0292536 -0.0972966" quat="0.922285 0.098826 0.0982562 -0.360514"
                      mass="2.32712" diaginertia="0.0182879 0.0182879 0.0182879"/>
                    <joint name="left_fr3_joint5" axis="0 0 1" range="-2.8065 2.8065" actuatorfrcrange="-12 12" frictionloss="0.5" damping="10.0"/>
                    <geom mesh="link5_0" material="white" class="visual"/>
                    <geom mesh="link5_1" material="white" class="visual"/>
                    <geom mesh="link5_2" material="black" class="visual"/>
                    <geom name="left_fr3_link5_collision" class="collision" mesh="link5_coll"/>
                    <body name="left_fr3_link6" quat="1 1 0 0">
                      <inertial pos="0.0597131 -0.0410295 -0.0101693" quat="0.593933 0.525442 0.520644 0.316361"
                        mass="1.81704" diaginertia="0.00483538 0.00483538 0.00483538"/>
                      <joint name="left_fr3_joint6" axis="0 0 1" range="0.5445 4.5169" actuatorfrcrange="-12 12" frictionloss="0.5" damping="10.0"/>
                      <geom mesh="link6_0" material="button_green" class="visual"/>
                      <geom mesh="link6_1" material="white" class="visual"/>
                      <geom mesh="link6_2" material="white" class="visual"/>
                      <geom mesh="link6_3" material="gray" class="visual"/>
                      <geom mesh="link6_4" material="button_red" class="visual"/>
                      <geom mesh="link6_5" material="white" class="visual"/>
                      <geom mesh="link6_6" material="black" class="visual"/>
                      <geom mesh="link6_7" material="button_blue" class="visual"/>
                      <geom name="left_fr3_link6_collision" class="collision" mesh="link6_coll"/>
                      <body name="left_fr3_link7" pos="0.088 0 0" quat="1 1 0 0">
                        <inertial pos="0.00452258 0.00862619 -0.0161633" quat="0.120255 0.394761 -0.799132 0.437139"
                          mass="0.627143" diaginertia="3.076e-07 3.076e-07 3.076e-07"/>
                        <joint name="left_fr3_joint7" axis="0 0 1" range="-3.0159 3.0159" actuatorfrcrange="-12 12" frictionloss="0.5" damping="10.0"/>
                        <geom mesh="link7_0" material="black" class="visual"/>
                        <geom mesh="link7_1" material="white" class="visual"/>
                        <geom mesh="link7_2" material="white" class="visual"/>
                        <geom mesh="link7_3" material="black" class="visual"/>
                        <geom name="left_fr3_link7_collision" class="collision" mesh="link7_coll"/>
                        
                        <!-- Left Panda gripper/hand -->
                        <body name="left_hand" pos="0 0 0.107" quat="0.9238795 0 0 -0.3826834">
                          <inertial mass="0.73" pos="-0.01 0 0.03" diaginertia="0.001 0.0025 0.0017"/>
                          <geom mesh="hand_0" material="white" class="visual"/>
                          <geom mesh="hand_1" material="black" class="visual"/>
                          <geom mesh="hand_2" material="black" class="visual"/>
                          <geom mesh="hand_3" material="white" class="visual"/>
                          <geom mesh="hand_4" material="white" class="visual"/>
                          <geom mesh="hand_coll" class="collision"/>
                          <site name="left_gripper" pos="0 0 0.1"/>
                          <site name="left_attachment_site" pos="0 0 0.09"/>
                          <body name="left_left_finger" pos="0 0 0.0584">
                            <inertial mass="0.015" pos="0 0 0" diaginertia="2.375e-6 2.375e-6 7.5e-7"/>
                            <joint name="left_finger_joint1" class="finger" damping="10"/>
                            <geom mesh="finger_0" material="white" class="visual"/>
                            <geom mesh="finger_1" material="black" class="visual"/>
                          </body>
                          <body name="left_right_finger" pos="0 0 0.0584" quat="0 0 0 1">
                            <inertial mass="0.015" pos="0 0 0" diaginertia="2.375e-6 2.375e-6 7.5e-7"/>
                            <joint name="left_finger_joint2" class="finger" damping="10"/>
                            <geom mesh="finger_0" material="white" class="visual"/>
                            <geom mesh="finger_1" material="black" class="visual"/>
                          </body>
                        </body>
                      </body>
                    </body>
                  </body>
                </body>
              </body>
            </body>
          </body>
        </body>
      </body>

      <!-- RIGHT ARM -->
      <body name="right_base" pos="0.056 -0.119324 0.194376" quat="0.9239 0.3827 0 0" childclass="fr3">
        <body name="right_fr3_link0">
          <geom mesh="link0_0" material="black" class="visual"/>
          <geom mesh="link0_1" material="white" class="visual"/>
          <geom mesh="link0_2" material="white" class="visual"/>
          <geom mesh="link0_3" material="white" class="visual"/>
          <geom mesh="link0_4" material="white" class="visual"/>
          <geom mesh="link0_5" material="red" class="visual"/>
          <geom mesh="link0_6" material="black" class="visual"/>
          <geom name="right_fr3_link0_collision" mesh="link0_coll" class="collision"/>
          <body name="right_fr3_link1" pos="0 0 0.333">
            <inertial pos="4.128e-07 -0.0181251 -0.0386036" quat="0.999901 0.0021545 0.00429041 0.0132325" mass="2.92747"
              diaginertia="0.0186043 0.0181194 0.00538716"/>
            <joint name="right_fr3_joint1" axis="0 0 1" range="-2.7437 2.7437" actuatorfrcrange="-87 87" frictionloss="0.5" damping="10.0"/>
            <geom name="right_fr3_link1_collision" class="collision" mesh="link1_coll"/>
            <geom material="white" mesh="link1" class="visual"/>
            <body name="right_fr3_link2" quat="1 -1 0 0">
              <inertial pos="0.00318289 -0.0743222 0.00881461" quat="0.356855 0.680818 -0.434812 0.469126" mass="2.93554"
                diaginertia="0.0299291 0.0299291 0.0299291"/>
              <joint name="right_fr3_joint2" axis="0 0 1" range="-1.7837 1.7837" actuatorfrcrange="-87 87" frictionloss="0.5" damping="10.0"/>
              <geom material="white" mesh="link2" class="visual"/>
              <geom name="right_fr3_link2_collision" class="collision" mesh="link2_coll"/>
              <body name="right_fr3_link3" pos="0 -0.316 0" quat="1 1 0 0">
                <inertial pos="0.0407016 -0.00482006 -0.0289731" quat="0.950032 -0.148357 0.229935 0.150201" mass="2.2449"
                  diaginertia="0.0140109 0.0140109 0.0140109"/>
                <joint name="right_fr3_joint3" axis="0 0 1" range="-2.9007 2.9007" actuatorfrcrange="-87 87" frictionloss="0.5" damping="10.0"/>
                <geom mesh="link3_0" material="white" class="visual"/>
                <geom mesh="link3_1" material="black" class="visual"/>
                <geom name="right_fr3_link3_collision" class="collision" mesh="link3_coll"/>
                <body name="right_fr3_link4" pos="0.0825 0 0" quat="1 1 0 0">
                  <inertial pos="-0.0459101 0.0630493 -0.00851879" quat="0.23761 0.892458 -0.00078702 0.383484"
                    mass="2.6156" diaginertia="0.0206104 0.0206104 0.0206104"/>
                  <joint name="right_fr3_joint4" axis="0 0 1" range="-3.0421 -0.1518" actuatorfrcrange="-87 87" frictionloss="0.5" damping="10.0"/>
                  <geom mesh="link4_0" material="white" class="visual"/>
                  <geom mesh="link4_1" material="black" class="visual"/>
                  <geom name="right_fr3_link4_collision" class="collision" mesh="link4_coll"/>
                  <body name="right_fr3_link5" pos="-0.0825 0.384 0" quat="1 -1 0 0">
                    <inertial pos="-0.00160396 0.0292536 -0.0972966" quat="0.922285 0.098826 0.0982562 -0.360514"
                      mass="2.32712" diaginertia="0.0182879 0.0182879 0.0182879"/>
                    <joint name="right_fr3_joint5" axis="0 0 1" range="-2.8065 2.8065" actuatorfrcrange="-12 12" frictionloss="0.5" damping="10.0"/>
                    <geom mesh="link5_0" material="white" class="visual"/>
                    <geom mesh="link5_1" material="white" class="visual"/>
                    <geom mesh="link5_2" material="black" class="visual"/>
                    <geom name="right_fr3_link5_collision" class="collision" mesh="link5_coll"/>
                    <body name="right_fr3_link6" quat="1 1 0 0">
                      <inertial pos="0.0597131 -0.0410295 -0.0101693" quat="0.593933 0.525442 0.520644 0.316361"
                        mass="1.81704" diaginertia="0.00483538 0.00483538 0.00483538"/>
                      <joint name="right_fr3_joint6" axis="0 0 1" range="0.5445 4.5169" actuatorfrcrange="-12 12" frictionloss="0.5" damping="10.0"/>
                      <geom mesh="link6_0" material="button_green" class="visual"/>
                      <geom mesh="link6_1" material="white" class="visual"/>
                      <geom mesh="link6_2" material="white" class="visual"/>
                      <geom mesh="link6_3" material="gray" class="visual"/>
                      <geom mesh="link6_4" material="button_red" class="visual"/>
                      <geom mesh="link6_5" material="white" class="visual"/>
                      <geom mesh="link6_6" material="black" class="visual"/>
                      <geom mesh="link6_7" material="button_blue" class="visual"/>
                      <geom name="right_fr3_link6_collision" class="collision" mesh="link6_coll"/>
                      <body name="right_fr3_link7" pos="0.088 0 0" quat="1 1 0 0">
                        <inertial pos="0.00452258 0.00862619 -0.0161633" quat="0.120255 0.394761 -0.799132 0.437139"
                          mass="0.627143" diaginertia="3.076e-07 3.076e-07 3.076e-07"/>
                        <joint name="right_fr3_joint7" axis="0 0 1" range="-3.0159 3.0159" actuatorfrcrange="-12 12" frictionloss="0.5" damping="10.0"/>
                        <geom mesh="link7_0" material="black" class="visual"/>
                        <geom mesh="link7_1" material="white" class="visual"/>
                        <geom mesh="link7_2" material="white" class="visual"/>
                        <geom mesh="link7_3" material="black" class="visual"/>
                        <geom name="right_fr3_link7_collision" class="collision" mesh="link7_coll"/>
                        
                        <!-- Right Panda gripper/hand -->
                        <body name="right_hand" pos="0 0 0.107" quat="0.9238795 0 0 -0.3826834">
                          <inertial mass="0.73" pos="-0.01 0 0.03" diaginertia="0.001 0.0025 0.0017"/>
                          <geom mesh="hand_0" material="white" class="visual"/>
                          <geom mesh="hand_1" material="black" class="visual"/>
                          <geom mesh="hand_2" material="black" class="visual"/>
                          <geom mesh="hand_3" material="white" class="visual"/>
                          <geom mesh="hand_4" material="white" class="visual"/>
                          <geom mesh="hand_coll" class="collision"/>
                          <site name="right_gripper" pos="0 0 0.1"/>
                          <site name="right_attachment_site" pos="0 0 0.09"/>
                          <body name="right_left_finger" pos="0 0 0.0584">
                            <inertial mass="0.015" pos="0 0 0" diaginertia="2.375e-6 2.375e-6 7.5e-7"/>
                            <joint name="right_finger_joint1" class="finger" damping="10"/>
                            <geom mesh="finger_0" material="white" class="visual"/>
                            <geom mesh="finger_1" material="black" class="visual"/>
                          </body>
                          <body name="right_right_finger" pos="0 0 0.0584" quat="0 0 0 1">
                            <inertial mass="0.015" pos="0 0 0" diaginertia="2.375e-6 2.375e-6 7.5e-7"/>
                            <joint name="right_finger_joint2" class="finger" damping="10"/>
                            <geom mesh="finger_0" material="white" class="visual"/>
                            <geom mesh="finger_1" material="black" class="visual"/>
                          </body>
                        </body>
                      </body>
                    </body>
                  </body>
                </body>
              </body>
            </body>
          </body>
        </body>
      </body>

    </body>



  </worldbody>

  <equality>
    <joint joint1="left_finger_joint1" joint2="left_finger_joint2" solimp="0.95 0.99 0.001" solref="0.005 1"/>
    <joint joint1="right_finger_joint1" joint2="right_finger_joint2" solimp="0.95 0.99 0.001" solref="0.005 1"/>
  </equality>

  <actuator>
    <!-- LEFT ARM ACTUATORS - Position control -->
    <position name="left_fr3_joint1_pos" joint="left_fr3_joint1" kp="100"/>
    <position name="left_fr3_joint2_pos" joint="left_fr3_joint2" kp="100"/>
    <position name="left_fr3_joint3_pos" joint="left_fr3_joint3" kp="100"/>
    <position name="left_fr3_joint4_pos" joint="left_fr3_joint4" kp="100"/>
    <position name="left_fr3_joint5_pos" joint="left_fr3_joint5" kp="100"/>
    <position name="left_fr3_joint6_pos" joint="left_fr3_joint6" kp="100"/>
    <position name="left_fr3_joint7_pos" joint="left_fr3_joint7" kp="100"/>
    
    <!-- RIGHT ARM ACTUATORS - Position control -->
    <position name="right_fr3_joint1_pos" joint="right_fr3_joint1" kp="100"/>
    <position name="right_fr3_joint2_pos" joint="right_fr3_joint2" kp="100"/>
    <position name="right_fr3_joint3_pos" joint="right_fr3_joint3" kp="100"/>
    <position name="right_fr3_joint4_pos" joint="right_fr3_joint4" kp="100"/>
    <position name="right_fr3_joint5_pos" joint="right_fr3_joint5" kp="100"/>
    <position name="right_fr3_joint6_pos" joint="right_fr3_joint6" kp="100"/>
    <position name="right_fr3_joint7_pos" joint="right_fr3_joint7" kp="100"/>
    
    <!-- GRIPPER ACTUATORS -->
    <general name="left_fingers_actuator" joint="left_finger_joint1" ctrlrange="0 0.04" gainprm="350 0 0" biasprm="0 -350 -10" forcerange="-200 200"/>
    <general name="right_fingers_actuator" joint="right_finger_joint1" ctrlrange="0 0.04" gainprm="350 0 0" biasprm="0 -350 -10" forcerange="-200 200"/>
  </actuator>

  <keyframe>
    <key name="home" qpos="0.0 -0.7853 0.0 -2.3561 0.0 1.5708 0.7853 0.04 0.04 0.0 -0.7853 0.0 -2.3561 0.0 1.5708 0.7853 0.04 0.04" 
         ctrl="0.0 -0.7853 0.0 -2.3561 0.0 1.5708 0.7853 0.04 0.0 -0.7853 0.0 -2.3561 0.0 1.5708 0.7853 0.04"/>
  </keyframe>

  <contact>
    <!-- Enable collisions between left and right arm links -->
    <pair geom1="left_fr3_link0_collision" geom2="right_fr3_link0_collision"/>
    <pair geom1="left_fr3_link1_collision" geom2="right_fr3_link1_collision"/>
    <pair geom1="left_fr3_link2_collision" geom2="right_fr3_link2_collision"/>
    <pair geom1="left_fr3_link3_collision" geom2="right_fr3_link3_collision"/>
    <pair geom1="left_fr3_link4_collision" geom2="right_fr3_link4_collision"/>
    <pair geom1="left_fr3_link5_collision" geom2="right_fr3_link5_collision"/>
    <pair geom1="left_fr3_link6_collision" geom2="right_fr3_link6_collision"/>
    <pair geom1="left_fr3_link7_collision" geom2="right_fr3_link7_collision"/>
  </contact>
</mujoco>
